<robot name="bipedal_rppr">
    <link name="basis">
    <inertial>
        <origin xyz="0 0 0.2" rpy="0 0 0"/>
        <mass value="2"/>
        <inertia ixx="1"  ixy="0"  ixz="0" iyy="1" iyz="0" izz="20" />
    </inertial>
    <visual>
        <origin xyz="0 0 0.2" rpy="0 0 0" />
        <geometry>
            <box size="0.08 0.22 0.42" />
        </geometry>
        <material name="black">
            <color rgba="0 0 0 1.0"/>
        </material>
    </visual>
    <collision>
        <origin xyz="0 0 0.2" rpy="0 0 0" />
        <geometry>
            <box size="0.08 0.22 0.42" />
        </geometry>
    </collision>
  </link>
  <link name="left_body_1">
  <inertial>
      <origin xyz="0 0 -0.1" rpy="0 0 0"/>
      <mass value="0.2"/>
      <inertia ixx="1"  ixy="0"  ixz="0" iyy="1" iyz="0" izz="5" />
  </inertial>
  <visual>
      <origin xyz="0.05 0.0 -0.05" rpy="0 0 0" />
      <geometry>
          <box size="0.02 0.02 0.12" />
      </geometry>
      <material name="blueishgreen">
          <color rgba="0 0.6 0.5 1.0"/>
      </material>
  </visual>
  <visual>
      <origin xyz="-0.05 0.0 -0.05" rpy="0 0 0" />
      <geometry>
          <box size="0.02 0.02 0.12" />
      </geometry>
      <material name="blueishgreen">
          <color rgba="0 0.6 0.5 1.0"/>
      </material>
  </visual>
  <visual>
      <origin xyz="0.0 0.0 -0.1" rpy="0 0 0" />
      <geometry>
          <box size="0.1 0.02 0.02" />
      </geometry>
      <material name="blueishgreen">
          <color rgba="0 0.6 0.5 1.0"/>
      </material>
  </visual>
  <collision>
      <origin xyz="0 0 -0.05" rpy="0 0 0"/>
      <geometry>
          <box size="0.12 0.02 0.12" />
      </geometry>
  </collision>
    </link>
    <link name="left_body_2">
    <inertial>
        <origin xyz="0 0 -0.15" rpy="0 0 0"/>
        <mass value="0.3"/>
        <inertia ixx="1"  ixy="0"  ixz="0" iyy="1" iyz="0" izz="5" />
    </inertial>
    <visual>
        <origin xyz="0 0.02 -0.15" rpy="0 0 0"/>
        <geometry>
            <box size="0.02 0.02 0.32" />
        </geometry>
        <material name="reddishpurple">
            <color rgba="0.8 0.6 0.7 1.0"/>
        </material>
    </visual>
    <collision>
        <origin xyz="0 0.0 -0.15" rpy="0 0 0"/>
        <geometry>
            <box size="0.02 0.06 0.32" />
        </geometry>
    </collision>
    </link>
    <link name="left_body_3">
    <inertial>
        <origin xyz="0 0.0 -0.15" rpy="0 0 0"/>
        <mass value="0.3"/>
        <inertia ixx="1"  ixy="0"  ixz="0" iyy="1" iyz="0" izz="5" />
    </inertial>
    <visual>
        <origin xyz="0 0.0 -0.15" rpy="0 0 0"/>
        <geometry>
            <box size="0.02 0.02 0.32" />
        </geometry>
        <material name="skyblue">
            <color rgba="0.35 0.7 0.9 1.0"/>
        </material>
    </visual>
    <collision>
        <origin xyz="0 0.0 -0.15" rpy="0 0 0"/>
        <geometry>
            <box size="0.02 0.02 0.32" />
        </geometry>
    </collision>
    </link>
    <link name="left_foot">
    <inertial>
        <origin xyz="0 0 -0.05" rpy="0 0 0"/>
        <mass value="0.3"/>
        <inertia ixx="1"  ixy="0"  ixz="0" iyy="10" iyz="0" izz="1" />
    </inertial>
    <visual>
        <origin xyz="0.02 0.0 -0.01" rpy="0 0 0"/>
        <geometry>
            <box size="0.02 0.02 0.04" />
        </geometry>
        <material name="reddishpurple">
            <color rgba="0.8 0.6 0.7 1.0"/>
        </material>
    </visual>
    <visual>
        <origin xyz="-0.02 0.0 -0.01" rpy="0 0 0"/>
        <geometry>
            <box size="0.02 0.02 0.04" />
        </geometry>
        <material name="reddishpurple">
            <color rgba="0.8 0.6 0.7 1.0"/>
        </material>
    </visual>
    <visual>
        <origin xyz="0 0 -0.04" rpy="0 0 0" />
        <geometry>
            <box size="0.2 0.1 0.02" />
        </geometry>
        <material name="blueishgreen">
            <color rgba="0 0.6 0.5 1.0"/>
        </material>
    </visual>
    <collision>
        <origin xyz="0 0.0 -0.04" rpy="0 0 0"/>
        <geometry>
            <box size="0.1 0.05 0.02" />
        </geometry>
    </collision>
    </link>
    <joint name="left_hip_roll" type="continuous">
        <origin xyz="0 0.1 0" rpy="0 0 0"/>
        <parent link="basis" />
        <child link="left_body_1" />
        <axis xyz="1 0 0" />
        <dynamics damping="0.02" friction="0.01" />
        <limit effort="5.0"/>
    </joint>
    <joint name="left_hip_pitch" type="continuous">
        <origin xyz="0.0 0.0 -0.1" rpy="0 0 0"/>
        <parent link="left_body_1" />
        <child link="left_body_2" />
        <axis xyz="0 1 0" />
        <dynamics damping="0.02" friction="0.01" />
        <limit effort="5.0"/>
    </joint>
    <joint name="left_knee" type="continuous">
        <origin xyz="0.0 0.0 -0.3" rpy="0 0 0"/>
        <parent link="left_body_2" />
        <child link="left_body_3" />
        <axis xyz="0 1 0" />
        <dynamics damping="0.02" friction="0.01" />
        <limit effort="10.0"/>
    </joint>
    <joint name="left_ankle" type="continuous">
        <origin xyz="0.0 0.0 -0.3" rpy="0 0 0"/>
        <parent link="left_body_3" />
        <child link="left_foot" />
        <axis xyz="1 0 0" />
        <dynamics damping="0.02" friction="0.01" />
        <limit effort="2.0"/>
    </joint>
  <link name="right_body_1">
  <inertial>
      <origin xyz="0 0 -0.1" rpy="0 0 0"/>
      <mass value="0.2"/>
      <inertia ixx="1"  ixy="0"  ixz="0" iyy="1" iyz="0" izz="5" />
  </inertial>
  <visual>
      <origin xyz="0.05 0.0 -0.05" rpy="0 0 0" />
      <geometry>
          <box size="0.02 0.02 0.12" />
      </geometry>
      <material name="blueishgreen">
          <color rgba="0 0.6 0.5 1.0"/>
      </material>
  </visual>
  <visual>
      <origin xyz="-0.05 0.0 -0.05" rpy="0 0 0" />
      <geometry>
          <box size="0.02 0.02 0.12" />
      </geometry>
      <material name="blueishgreen">
          <color rgba="0 0.6 0.5 1.0"/>
      </material>
  </visual>
  <visual>
      <origin xyz="0.0 0.0 -0.1" rpy="0 0 0" />
      <geometry>
          <box size="0.1 0.02 0.02" />
      </geometry>
      <material name="blueishgreen">
          <color rgba="0 0.6 0.5 1.0"/>
      </material>
  </visual>
  <collision>
      <origin xyz="0 0 -0.05" rpy="0 0 0"/>
      <geometry>
          <box size="0.12 0.02 0.12" />
      </geometry>
  </collision>
    </link>
    <link name="right_body_2">
    <inertial>
        <origin xyz="0 0 -0.15" rpy="0 0 0"/>
        <mass value="0.3"/>
        <inertia ixx="1"  ixy="0"  ixz="0" iyy="1" iyz="0" izz="5" />
    </inertial>
    <visual>
        <origin xyz="0 0.02 -0.15" rpy="0 0 0"/>
        <geometry>
            <box size="0.02 0.02 0.32" />
        </geometry>
        <material name="reddishpurple">
            <color rgba="0.8 0.6 0.7 1.0"/>
        </material>
    </visual>
    <collision>
        <origin xyz="0 0.0 -0.15" rpy="0 0 0"/>
        <geometry>
            <box size="0.02 0.06 0.32" />
        </geometry>
    </collision>
    </link>
    <link name="right_body_3">
    <inertial>
        <origin xyz="0 0.0 -0.15" rpy="0 0 0"/>
        <mass value="0.3"/>
        <inertia ixx="1"  ixy="0"  ixz="0" iyy="1" iyz="0" izz="5" />
    </inertial>
    <visual>
        <origin xyz="0 0.0 -0.15" rpy="0 0 0"/>
        <geometry>
            <box size="0.02 0.02 0.32" />
        </geometry>
        <material name="skyblue">
            <color rgba="0.35 0.7 0.9 1.0"/>
        </material>
    </visual>
    <collision>
        <origin xyz="0 0.0 -0.15" rpy="0 0 0"/>
        <geometry>
            <box size="0.02 0.02 0.32" />
        </geometry>
    </collision>
    </link>
    <link name="right_foot">
    <inertial>
        <origin xyz="0 0 -0.05" rpy="0 0 0"/>
        <mass value="0.3"/>
        <inertia ixx="1"  ixy="0"  ixz="0" iyy="10" iyz="0" izz="1" />
    </inertial>
    <visual>
        <origin xyz="0.02 0.0 -0.01" rpy="0 0 0"/>
        <geometry>
            <box size="0.02 0.02 0.04" />
        </geometry>
        <material name="reddishpurple">
            <color rgba="0.8 0.6 0.7 1.0"/>
        </material>
    </visual>
    <visual>
        <origin xyz="-0.02 0.0 -0.01" rpy="0 0 0"/>
        <geometry>
            <box size="0.02 0.02 0.04" />
        </geometry>
        <material name="reddishpurple">
            <color rgba="0.8 0.6 0.7 1.0"/>
        </material>
    </visual>
    <visual>
        <origin xyz="0 0 -0.04" rpy="0 0 0" />
        <geometry>
            <box size="0.2 0.1 0.02" />
        </geometry>
        <material name="blueishgreen">
            <color rgba="0 0.6 0.5 1.0"/>
        </material>
    </visual>
    <collision>
        <origin xyz="0 0.0 -0.04" rpy="0 0 0"/>
        <geometry>
            <box size="0.1 0.05 0.02" />
        </geometry>
    </collision>
    </link>
    <joint name="right_hip_roll" type="continuous">
        <origin xyz="0 -0.1 0" rpy="0 0 0"/>
        <parent link="basis" />
        <child link="right_body_1" />
        <axis xyz="1 0 0" />
        <dynamics damping="0.02" friction="0.01" />
        <limit effort="5.0"/>
    </joint>
    <joint name="right_hip_pitch" type="continuous">
        <origin xyz="0.0 0.0 -0.1" rpy="0 0 0"/>
        <parent link="right_body_1" />
        <child link="right_body_2" />
        <axis xyz="0 1 0" />
        <dynamics damping="0.02" friction="0.01" />
        <limit effort="5.0"/>
    </joint>
    <joint name="right_knee" type="continuous">
        <origin xyz="0.0 0.0 -0.3" rpy="0 0 0"/>
        <parent link="right_body_2" />
        <child link="right_body_3" />
        <axis xyz="0 1 0" />
        <dynamics damping="0.02" friction="0.01" />
        <limit effort="10.0"/>
    </joint>
    <joint name="right_ankle" type="continuous">
        <origin xyz="0.0 0.0 -0.3" rpy="0 0 0"/>
        <parent link="right_body_3" />
        <child link="right_foot" />
        <axis xyz="1 0 0" />
        <dynamics damping="0.02" friction="0.01" />
        <limit effort="2.0"/>
    </joint>
</robot>
