<robot name="leg">
  <link name="basis">
    <inertial>
      <origin xyz="0 0 0.5" rpy="0 0 0"/>
      <mass value="1"/>
      <inertia ixx="1"  ixy="0"  ixz="0" iyy="1" iyz="0" izz="100" />
    </inertial>
    <visual>
      <origin xyz="0 0 0.5" rpy="0 0 0" />
      <geometry>
        <cylinder radius="0.05" length="1" />
      </geometry>
      <material name="black">
        <color rgba="0 0 0 1.0"/>
      </material>
    </visual>
    <collision>
      <origin xyz="0 0 0.5" rpy="0 0 0"/>
      <geometry>
        <box size="0.1 0.1 1" />
      </geometry>
    </collision>
  </link>
  <link name="body1">
    <inertial>
      <origin xyz="0 0.2 0" rpy="0 0 0"/>
      <mass value="0.5"/>
      <inertia ixx="25"  ixy="0"  ixz="0" iyy="1" iyz="0" izz="1" />
    </inertial>
    <visual>
      <origin xyz="0 0.2 0" rpy="0 0 0" />
      <geometry>
        <box size="0.02 0.42 0.02" />
      </geometry>
      <material name="blueishgreen">
        <color rgba="0 0.6 0.5 1.0"/>
      </material>
    </visual>
    <collision>
      <origin xyz="0 0.2 0" rpy="0 0 0"/>
      <geometry>
        <box size="0.02 0.42 0.02" />
      </geometry>
    </collision>
  </link>
  <link name="body2">
    <inertial>
      <origin xyz="0 0.15 0" rpy="0 0 0"/>
      <mass value="0.5"/>
      <inertia ixx="1"  ixy="0"  ixz="0" iyy="10" iyz="0" izz="1" />
    </inertial>
    <visual>
      <origin xyz="0 0.15 0" rpy="0 0 0" />
      <geometry>
        <box size="0.02 0.32 0.02" />
      </geometry>
      <material name="reddishpurple">
        <color rgba="0.8 0.6 0.7 1.0"/>
      </material>
    </visual>
    <collision>
      <origin xyz="0 0.15 0" rpy="0 0 0"/>
      <geometry>
        <box size="0.02 0.32 0.02" />
      </geometry>
    </collision>
  </link>
  <link name="body3">
    <inertial>
      <origin xyz="0 0.15 0" rpy="0 0 0"/>
      <mass value="0.5"/>
      <inertia ixx="1"  ixy="0"  ixz="0" iyy="10" iyz="0" izz="1" />
    </inertial>
    <visual>
      <origin xyz="0 0.15 0" rpy="0 0 0" />
      <geometry>
        <box size="0.02 0.32 0.02" />
      </geometry>
      <material name="skyblue">
        <color rgba="0.35 0.7 0.9 1.0"/>
      </material>
    </visual>
    <collision>
      <origin xyz="0 0.15 0" rpy="0 0 0"/>
      <geometry>
        <box size="0.02 0.32 0.02" />
      </geometry>
    </collision>
  </link>
  <link name="body4">
    <inertial>
      <origin xyz="0 0.095 0" rpy="0 0 0"/>
      <mass value="0.5"/>
      <inertia ixx="1"  ixy="0"  ixz="0" iyy="10" iyz="0" izz="1" />
    </inertial>
    <visual>
      <origin xyz="0 0.095 0" rpy="0 0 0" />
      <geometry>
        <box size="0.02 0.21 0.02" />
      </geometry>
      <material name="blueishgreen">
        <color rgba="0 0.6 0.5 1.0"/>
      </material>
    </visual>
    <visual>
      <origin xyz="0 0.195 0" rpy="0 0 0" />
      <geometry>
        <box size="0.05 0.01 0.05" />
      </geometry>
      <material name="blueishgreen">
        <color rgba="0 0.6 0.5 1.0"/>
      </material>
    </visual>
    <collision>
      <origin xyz="0 0.095 0" rpy="0 0 0"/>
      <geometry>
        <box size="0.02 0.21 0.02" />
      </geometry>
    </collision>
  </link>
  <joint name="dof1" type="continuous">
    <origin xyz="0 0 1.01" rpy="0 0 0"/>
    <parent link="basis" />
    <child link="body1" />
    <axis xyz="0 0 1" />
  </joint>
  <joint name="dof2" type="continuous">
    <origin xyz="0.02 0.4 0" rpy="0 0 0"/>
    <parent link="body1" />
    <child link="body2" />
    <axis xyz="1 0 0" />
  </joint>
  <joint name="dof3" type="continuous">
    <origin xyz="-0.02 0.3 0" rpy="0 0 0"/>
    <parent link="body2" />
    <child link="body3" />
    <axis xyz="1 0 0" />
  </joint>
  <joint name="dof4" type="continuous">
    <origin xyz="0.02 0.3 0" rpy="0 0 0"/>
    <parent link="body3" />
    <child link="body4" />
    <axis xyz="1 0 0" />
  </joint>
</robot>
